<?xml version="1.0" encoding="utf-8"?>
<!-- =================================================================================== -->
<!-- |    This document was autogenerated by xacro from drone.urdf.xacro               | -->
<!-- |    EDITING THIS FILE BY HAND IS NOT RECOMMENDED                                 | -->
<!-- =================================================================================== -->
<robot name="wasp">
  <material name="black">
    <color rgba="0.0 0.0 0.0 1.0"/>
  </material>
  <material name="blue">
    <color rgba="0.0 0.0 0.8 1.0"/>
  </material>
  <material name="green">
    <color rgba="0.0 0.8 0.0 1.0"/>
  </material>
  <material name="grey">
    <color rgba="0.2 0.2 0.2 1.0"/>
  </material>
  <material name="orange">
    <color rgba="1.0 0.423529411765 0.0392156862745 1.0"/>
  </material>
  <material name="brown">
    <color rgba="0.870588235294 0.811764705882 0.764705882353 1.0"/>
  </material>
  <material name="red">
    <color rgba="0.8 0.0 0.0 1.0"/>
  </material>
  <material name="white">
    <color rgba="1.0 1.0 1.0 1.0"/>
  </material>
  <link name="base_link">
    <collision name="frame">
      <origin rpy="0 0 0" xyz="0 0 0.02"/>
      <geometry>
        <cylinder length="0.04" radius="0.3"/>
      </geometry>
    </collision>
    <collision name="rollcage">
      <origin rpy="0 0 0" xyz="0 0 0.066"/>
      <geometry>
        <cylinder length="0.06" radius="0.10"/>
      </geometry>
    </collision>
    <collision name="lander">
      <origin rpy="0 0 0" xyz="0 0 -0.08"/>
      <geometry>
        <box size="0.3 0.2 0.16"/>
      </geometry>
    </collision>
    <inertial>
      <origin rpy="0 0 0" xyz="0 0 -0.1"/>
      <mass value="1.0"/>
      <inertia ixx="0.038" ixy="0.0" ixz="0.0" iyy="0.043" iyz="0.0" izz="0.0068"/>
    </inertial>
    <visual>
      <origin rpy="0 0 0" xyz="0 0 0"/>
      <geometry>
        <mesh filename="package://wasp_gazebo/meshes/core.dae"/>
      </geometry>
    </visual>
    <visual name="arm_0">
      <origin rpy="0 0 1.57079632679" xyz="0.075 0.0 0.0125"/>
      <geometry>
        <mesh filename="model://wasp/meshes/wasp_arm.dae"/>
      </geometry>
      <material name="black"/>
    </visual>
    <visual name="motor_0">
      <origin rpy="0 0 0" xyz="0.277 0.0 0.0125"/>
      <geometry>
        <mesh filename="model://wasp/meshes/wasp_motor.dae"/>
      </geometry>
      <material name="black"/>
    </visual>
    <visual name="arm_1">
      <origin rpy="0 0 2.61799387799" xyz="0.0375 0.0649519052838 0.0125"/>
      <geometry>
        <mesh filename="model://wasp/meshes/wasp_arm.dae"/>
      </geometry>
      <material name="black"/>
    </visual>
    <visual name="motor_1">
      <origin rpy="0 0 0" xyz="0.1385 0.239889036848 0.0125"/>
      <geometry>
        <mesh filename="model://wasp/meshes/wasp_motor.dae"/>
      </geometry>
      <material name="black"/>
    </visual>
    <visual name="arm_2">
      <origin rpy="0 0 3.66519142919" xyz="-0.0375 0.0649519052838 0.0125"/>
      <geometry>
        <mesh filename="model://wasp/meshes/wasp_arm.dae"/>
      </geometry>
      <material name="black"/>
    </visual>
    <visual name="motor_2">
      <origin rpy="0 0 0" xyz="-0.1385 0.239889036848 0.0125"/>
      <geometry>
        <mesh filename="model://wasp/meshes/wasp_motor.dae"/>
      </geometry>
      <material name="black"/>
    </visual>
    <visual name="arm_3">
      <origin rpy="0 0 4.71238898038" xyz="-0.075 9.18485099361e-18 0.0125"/>
      <geometry>
        <mesh filename="model://wasp/meshes/wasp_arm.dae"/>
      </geometry>
      <material name="black"/>
    </visual>
    <visual name="motor_3">
      <origin rpy="0 0 0" xyz="-0.277 3.39227163364e-17 0.0125"/>
      <geometry>
        <mesh filename="model://wasp/meshes/wasp_motor.dae"/>
      </geometry>
      <material name="black"/>
    </visual>
    <visual name="arm_4">
      <origin rpy="0 0 5.75958653158" xyz="-0.0375 -0.0649519052838 0.0125"/>
      <geometry>
        <mesh filename="model://wasp/meshes/wasp_arm.dae"/>
      </geometry>
      <material name="black"/>
    </visual>
    <visual name="motor_4">
      <origin rpy="0 0 0" xyz="-0.1385 -0.239889036848 0.0125"/>
      <geometry>
        <mesh filename="model://wasp/meshes/wasp_motor.dae"/>
      </geometry>
      <material name="black"/>
    </visual>
    <visual name="arm_5">
      <origin rpy="0 0 6.80678408278" xyz="0.0375 -0.0649519052838 0.0125"/>
      <geometry>
        <mesh filename="model://wasp/meshes/wasp_arm.dae"/>
      </geometry>
      <material name="black"/>
    </visual>
    <visual name="motor_5">
      <origin rpy="0 0 0" xyz="0.1385 -0.239889036848 0.0125"/>
      <geometry>
        <mesh filename="model://wasp/meshes/wasp_motor.dae"/>
      </geometry>
      <material name="black"/>
    </visual>
    <visual name="leg_0">
      <origin rpy="0 0 2.07750481931" xyz="0.0804398886853 0.0446477805529 -0.063"/>
      <geometry>
        <mesh filename="model://wasp/meshes/wasp_leg.dae"/>
      </geometry>
      <material name="black"/>
    </visual>
    <visual name="leg_1">
      <origin rpy="0 0 1.06408783428" xyz="0.0804398886853 -0.0446477805529 -0.063"/>
      <geometry>
        <mesh filename="model://wasp/meshes/wasp_leg.dae"/>
      </geometry>
      <material name="black"/>
    </visual>
    <visual name="leg_2">
      <origin rpy="0 0 5.2190974729" xyz="-0.0804398886853 -0.0446477805529 -0.063"/>
      <geometry>
        <mesh filename="model://wasp/meshes/wasp_leg.dae"/>
      </geometry>
      <material name="black"/>
    </visual>
    <visual name="leg_3">
      <origin rpy="0 0 4.20568048787" xyz="-0.0804398886853 0.0446477805529 -0.063"/>
      <geometry>
        <mesh filename="model://wasp/meshes/wasp_leg.dae"/>
      </geometry>
      <material name="black"/>
    </visual>
  </link>
  <joint name="rotor_0_joint" type="continuous">
    <parent link="base_link"/>
    <child link="rotor_0"/>
    <origin rpy="0 0 0" xyz="0.277 0.0 0.042"/>
    <axis xyz="0 0 1"/>
    <dynamics damping="0.004"/>
  </joint>
  <link name="rotor_0">
    <collision>
      <origin rpy="0 0 1.57079632679" xyz="0 0 0"/>
      <geometry>
        <cylinder length="0.01" radius="0.13"/>
      </geometry>
    </collision>
    <inertial>
      <origin rpy="0 0 1.57079632679" xyz="0 0 0"/>
      <mass value="0.025"/>
      <inertia ixx="9.750e-06" ixy="0.0" ixz="0.0" iyy="166.7e-06" iyz="0.0" izz="166.7e-06"/>
    </inertial>
    <visual>
      <origin rpy="0 0 1.57079632679" xyz="0 0 0"/>
      <geometry>
        <mesh filename="model://wasp/meshes/wasp_prop_cw.dae"/>
      </geometry>
      <material name="red"/>
    </visual>
  </link>
  <joint name="rotor_1_joint" type="continuous">
    <parent link="base_link"/>
    <child link="rotor_1"/>
    <origin rpy="0 0 0" xyz="0.1385 0.239889036848 0.042"/>
    <axis xyz="0 0 1"/>
    <dynamics damping="0.004"/>
  </joint>
  <link name="rotor_1">
    <collision>
      <origin rpy="0 0 2.61799387799" xyz="0 0 0"/>
      <geometry>
        <cylinder length="0.01" radius="0.13"/>
      </geometry>
    </collision>
    <inertial>
      <origin rpy="0 0 2.61799387799" xyz="0 0 0"/>
      <mass value="0.025"/>
      <inertia ixx="9.750e-06" ixy="0.0" ixz="0.0" iyy="166.7e-06" iyz="0.0" izz="166.7e-06"/>
    </inertial>
    <visual>
      <origin rpy="0 0 2.61799387799" xyz="0 0 0"/>
      <geometry>
        <mesh filename="model://wasp/meshes/wasp_prop_ccw.dae"/>
      </geometry>
      <material name="blue"/>
    </visual>
  </link>
  <joint name="rotor_2_joint" type="continuous">
    <parent link="base_link"/>
    <child link="rotor_2"/>
    <origin rpy="0 0 0" xyz="-0.1385 0.239889036848 0.042"/>
    <axis xyz="0 0 1"/>
    <dynamics damping="0.004"/>
  </joint>
  <link name="rotor_2">
    <collision>
      <origin rpy="0 0 3.66519142919" xyz="0 0 0"/>
      <geometry>
        <cylinder length="0.01" radius="0.13"/>
      </geometry>
    </collision>
    <inertial>
      <origin rpy="0 0 3.66519142919" xyz="0 0 0"/>
      <mass value="0.025"/>
      <inertia ixx="9.750e-06" ixy="0.0" ixz="0.0" iyy="166.7e-06" iyz="0.0" izz="166.7e-06"/>
    </inertial>
    <visual>
      <origin rpy="0 0 3.66519142919" xyz="0 0 0"/>
      <geometry>
        <mesh filename="model://wasp/meshes/wasp_prop_cw.dae"/>
      </geometry>
      <material name="red"/>
    </visual>
  </link>
  <joint name="rotor_3_joint" type="continuous">
    <parent link="base_link"/>
    <child link="rotor_3"/>
    <origin rpy="0 0 0" xyz="-0.277 3.39227163364e-17 0.042"/>
    <axis xyz="0 0 1"/>
    <dynamics damping="0.004"/>
  </joint>
  <link name="rotor_3">
    <collision>
      <origin rpy="0 0 4.71238898038" xyz="0 0 0"/>
      <geometry>
        <cylinder length="0.01" radius="0.13"/>
      </geometry>
    </collision>
    <inertial>
      <origin rpy="0 0 4.71238898038" xyz="0 0 0"/>
      <mass value="0.025"/>
      <inertia ixx="9.750e-06" ixy="0.0" ixz="0.0" iyy="166.7e-06" iyz="0.0" izz="166.7e-06"/>
    </inertial>
    <visual>
      <origin rpy="0 0 4.71238898038" xyz="0 0 0"/>
      <geometry>
        <mesh filename="model://wasp/meshes/wasp_prop_ccw.dae"/>
      </geometry>
      <material name="blue"/>
    </visual>
  </link>
  <joint name="rotor_4_joint" type="continuous">
    <parent link="base_link"/>
    <child link="rotor_4"/>
    <origin rpy="0 0 0" xyz="-0.1385 -0.239889036848 0.042"/>
    <axis xyz="0 0 1"/>
    <dynamics damping="0.004"/>
  </joint>
  <link name="rotor_4">
    <collision>
      <origin rpy="0 0 5.75958653158" xyz="0 0 0"/>
      <geometry>
        <cylinder length="0.01" radius="0.13"/>
      </geometry>
    </collision>
    <inertial>
      <origin rpy="0 0 5.75958653158" xyz="0 0 0"/>
      <mass value="0.025"/>
      <inertia ixx="9.750e-06" ixy="0.0" ixz="0.0" iyy="166.7e-06" iyz="0.0" izz="166.7e-06"/>
    </inertial>
    <visual>
      <origin rpy="0 0 5.75958653158" xyz="0 0 0"/>
      <geometry>
        <mesh filename="model://wasp/meshes/wasp_prop_cw.dae"/>
      </geometry>
      <material name="red"/>
    </visual>
  </link>
  <joint name="rotor_5_joint" type="continuous">
    <parent link="base_link"/>
    <child link="rotor_5"/>
    <origin rpy="0 0 0" xyz="0.1385 -0.239889036848 0.042"/>
    <axis xyz="0 0 1"/>
    <dynamics damping="0.004"/>
  </joint>
  <link name="rotor_5">
    <collision>
      <origin rpy="0 0 6.80678408278" xyz="0 0 0"/>
      <geometry>
        <cylinder length="0.01" radius="0.13"/>
      </geometry>
    </collision>
    <inertial>
      <origin rpy="0 0 6.80678408278" xyz="0 0 0"/>
      <mass value="0.025"/>
      <inertia ixx="9.750e-06" ixy="0.0" ixz="0.0" iyy="166.7e-06" iyz="0.0" izz="166.7e-06"/>
    </inertial>
    <visual>
      <origin rpy="0 0 6.80678408278" xyz="0 0 0"/>
      <geometry>
        <mesh filename="model://wasp/meshes/wasp_prop_ccw.dae"/>
      </geometry>
      <material name="blue"/>
    </visual>
  </link>
  <gazebo reference="base_link">
    <selfCollide>false</selfCollide>
    <maxVel>100.0</maxVel>
    <minDepth>0.001</minDepth>
    <mu1 value="200.0"/>
    <mu2 value="100.0"/>
    <kp value="10000000.0"/>
    <kd value="1.0"/>
  </gazebo>
  <gazebo>
    <link name="wasp/ground_truth/odometry_sensorgt_link">
      <pose>0 0 0 0 -0 0</pose>
      <inertial>
        <pose>0 0 0 0 -0 0</pose>
        <mass>0.15</mass>
        <inertia>
          <ixx>0.0001</ixx>
          <ixy>0</ixy>
          <ixz>0</ixz>
          <iyy>0.0002</iyy>
          <iyz>0</iyz>
          <izz>0.0002</izz>
        </inertia>
      </inertial>
      <self_collide>0</self_collide>
    </link>
    <joint name="wasp/ground_truth/odometry_sensorgt_joint" type="revolute">
      <child>wasp/ground_truth/odometry_sensorgt_link</child>
      <parent>base_link</parent>
      <axis>
        <xyz>0 0 1</xyz>
        <limit>
          <lower>0</lower>
          <upper>0</upper>
          <effort>0</effort>
          <velocity>0</velocity>
        </limit>
        <dynamics>
          <damping>1.0</damping>
        </dynamics>
        <use_parent_model_frame>1</use_parent_model_frame>
      </axis>
      <physics>
        <ode>
          <implicit_spring_damper>1</implicit_spring_damper>
        </ode>
      </physics>
    </joint>
    <link name="wasp/imu_link">
      <inertial>
        <pose>0 0 0 0 0 0</pose>
        <mass>0.15</mass>
        <inertia>
          <ixx>0.00001</ixx>
          <ixy>0</ixy>
          <ixz>0</ixz>
          <iyy>0.00002</iyy>
          <iyz>0</iyz>
          <izz>0.00002</izz>
        </inertia>
      </inertial>
      <sensor name="imu_sensor" type="imu">
        <pose>0 0 0 3.141593 0 0</pose>
        <always_on>1</always_on>
        <update_rate>1000.0</update_rate>
      </sensor>
      <self_collide>0</self_collide>
    </link>
    <joint name="wasp/imu_joint" type="revolute">
      <child>wasp/imu_link</child>
      <parent>base_link</parent>
      <axis>
        <xyz>0 0 1</xyz>
        <limit>
          <lower>0</lower>
          <upper>0</upper>
          <effort>0</effort>
          <velocity>0</velocity>
        </limit>
        <dynamics>
          <damping>1.0</damping>
        </dynamics>
        <use_parent_model_frame>1</use_parent_model_frame>
      </axis>
      <physics>
        <ode>
          <implicit_spring_damper>1</implicit_spring_damper>
        </ode>
      </physics>
    </joint>
  </gazebo>
  <gazebo reference="rotor_0">
    <material>Gazebo/Red</material>
    <self_collide>0</self_collide>
  </gazebo>
  <gazebo>
    <plugin filename="libLiftDragPlugin.so" name="rotor_0_blade_1">
      <a0>0.3</a0>
      <alpha_stall>1.4</alpha_stall>
      <cla>4.2500</cla>
      <cda>0.10</cda>
      <cma>0.00</cma>
      <cla_stall>-0.025</cla_stall>
      <cda_stall>0.0</cda_stall>
      <cma_stall>0.0</cma_stall>
      <area>0.002</area>
      <air_density>1.2041</air_density>
      <cp>0.084 0 0</cp>
      <forward>0 1 0</forward>
      <upward>0 0 1</upward>
      <link_name>wasp::rotor_0</link_name>
    </plugin>
    <plugin filename="libLiftDragPlugin.so" name="rotor_0_blade_2">
      <a0>0.3</a0>
      <alpha_stall>1.4</alpha_stall>
      <cla>4.2500</cla>
      <cda>0.10</cda>
      <cma>0.00</cma>
      <cla_stall>-0.025</cla_stall>
      <cda_stall>0.0</cda_stall>
      <cma_stall>0.0</cma_stall>
      <area>0.002</area>
      <air_density>1.2041</air_density>
      <cp>-0.084 0 0</cp>
      <forward>0 -1 0</forward>
      <upward>0 0 1</upward>
      <link_name>wasp::rotor_0</link_name>
    </plugin>
  </gazebo>
  <gazebo reference="rotor_1">
    <material>Gazebo/Blue</material>
    <self_collide>0</self_collide>
  </gazebo>
  <gazebo>
    <plugin filename="libLiftDragPlugin.so" name="rotor_1_blade_1">
      <a0>0.3</a0>
      <alpha_stall>1.4</alpha_stall>
      <cla>4.2500</cla>
      <cda>0.10</cda>
      <cma>0.00</cma>
      <cla_stall>-0.025</cla_stall>
      <cda_stall>0.0</cda_stall>
      <cma_stall>0.0</cma_stall>
      <area>0.002</area>
      <air_density>1.2041</air_density>
      <cp>0.084 0 0</cp>
      <forward>0 -1 0</forward>
      <upward>0 0 1</upward>
      <link_name>wasp::rotor_1</link_name>
    </plugin>
    <plugin filename="libLiftDragPlugin.so" name="rotor_1_blade_2">
      <a0>0.3</a0>
      <alpha_stall>1.4</alpha_stall>
      <cla>4.2500</cla>
      <cda>0.10</cda>
      <cma>0.00</cma>
      <cla_stall>-0.025</cla_stall>
      <cda_stall>0.0</cda_stall>
      <cma_stall>0.0</cma_stall>
      <area>0.002</area>
      <air_density>1.2041</air_density>
      <cp>-0.084 0 0</cp>
      <forward>0 1 0</forward>
      <upward>0 0 1</upward>
      <link_name>wasp::rotor_1</link_name>
    </plugin>
  </gazebo>
  <gazebo reference="rotor_2">
    <material>Gazebo/Red</material>
    <self_collide>0</self_collide>
  </gazebo>
  <gazebo>
    <plugin filename="libLiftDragPlugin.so" name="rotor_2_blade_1">
      <a0>0.3</a0>
      <alpha_stall>1.4</alpha_stall>
      <cla>4.2500</cla>
      <cda>0.10</cda>
      <cma>0.00</cma>
      <cla_stall>-0.025</cla_stall>
      <cda_stall>0.0</cda_stall>
      <cma_stall>0.0</cma_stall>
      <area>0.002</area>
      <air_density>1.2041</air_density>
      <cp>0.084 0 0</cp>
      <forward>0 1 0</forward>
      <upward>0 0 1</upward>
      <link_name>wasp::rotor_2</link_name>
    </plugin>
    <plugin filename="libLiftDragPlugin.so" name="rotor_2_blade_2">
      <a0>0.3</a0>
      <alpha_stall>1.4</alpha_stall>
      <cla>4.2500</cla>
      <cda>0.10</cda>
      <cma>0.00</cma>
      <cla_stall>-0.025</cla_stall>
      <cda_stall>0.0</cda_stall>
      <cma_stall>0.0</cma_stall>
      <area>0.002</area>
      <air_density>1.2041</air_density>
      <cp>-0.084 0 0</cp>
      <forward>0 -1 0</forward>
      <upward>0 0 1</upward>
      <link_name>wasp::rotor_2</link_name>
    </plugin>
  </gazebo>
  <gazebo reference="rotor_3">
    <material>Gazebo/Blue</material>
    <self_collide>0</self_collide>
  </gazebo>
  <gazebo>
    <plugin filename="libLiftDragPlugin.so" name="rotor_3_blade_1">
      <a0>0.3</a0>
      <alpha_stall>1.4</alpha_stall>
      <cla>4.2500</cla>
      <cda>0.10</cda>
      <cma>0.00</cma>
      <cla_stall>-0.025</cla_stall>
      <cda_stall>0.0</cda_stall>
      <cma_stall>0.0</cma_stall>
      <area>0.002</area>
      <air_density>1.2041</air_density>
      <cp>0.084 0 0</cp>
      <forward>0 -1 0</forward>
      <upward>0 0 1</upward>
      <link_name>wasp::rotor_3</link_name>
    </plugin>
    <plugin filename="libLiftDragPlugin.so" name="rotor_3_blade_2">
      <a0>0.3</a0>
      <alpha_stall>1.4</alpha_stall>
      <cla>4.2500</cla>
      <cda>0.10</cda>
      <cma>0.00</cma>
      <cla_stall>-0.025</cla_stall>
      <cda_stall>0.0</cda_stall>
      <cma_stall>0.0</cma_stall>
      <area>0.002</area>
      <air_density>1.2041</air_density>
      <cp>-0.084 0 0</cp>
      <forward>0 1 0</forward>
      <upward>0 0 1</upward>
      <link_name>wasp::rotor_3</link_name>
    </plugin>
  </gazebo>
  <gazebo reference="rotor_4">
    <material>Gazebo/Red</material>
    <self_collide>0</self_collide>
  </gazebo>
  <gazebo>
    <plugin filename="libLiftDragPlugin.so" name="rotor_4_blade_1">
      <a0>0.3</a0>
      <alpha_stall>1.4</alpha_stall>
      <cla>4.2500</cla>
      <cda>0.10</cda>
      <cma>0.00</cma>
      <cla_stall>-0.025</cla_stall>
      <cda_stall>0.0</cda_stall>
      <cma_stall>0.0</cma_stall>
      <area>0.002</area>
      <air_density>1.2041</air_density>
      <cp>0.084 0 0</cp>
      <forward>0 1 0</forward>
      <upward>0 0 1</upward>
      <link_name>wasp::rotor_4</link_name>
    </plugin>
    <plugin filename="libLiftDragPlugin.so" name="rotor_4_blade_2">
      <a0>0.3</a0>
      <alpha_stall>1.4</alpha_stall>
      <cla>4.2500</cla>
      <cda>0.10</cda>
      <cma>0.00</cma>
      <cla_stall>-0.025</cla_stall>
      <cda_stall>0.0</cda_stall>
      <cma_stall>0.0</cma_stall>
      <area>0.002</area>
      <air_density>1.2041</air_density>
      <cp>-0.084 0 0</cp>
      <forward>0 -1 0</forward>
      <upward>0 0 1</upward>
      <link_name>wasp::rotor_4</link_name>
    </plugin>
  </gazebo>
  <gazebo reference="rotor_5">
    <material>Gazebo/Blue</material>
    <self_collide>0</self_collide>
  </gazebo>
  <gazebo>
    <plugin filename="libLiftDragPlugin.so" name="rotor_5_blade_1">
      <a0>0.3</a0>
      <alpha_stall>1.4</alpha_stall>
      <cla>4.2500</cla>
      <cda>0.10</cda>
      <cma>0.00</cma>
      <cla_stall>-0.025</cla_stall>
      <cda_stall>0.0</cda_stall>
      <cma_stall>0.0</cma_stall>
      <area>0.002</area>
      <air_density>1.2041</air_density>
      <cp>0.084 0 0</cp>
      <forward>0 -1 0</forward>
      <upward>0 0 1</upward>
      <link_name>wasp::rotor_5</link_name>
    </plugin>
    <plugin filename="libLiftDragPlugin.so" name="rotor_5_blade_2">
      <a0>0.3</a0>
      <alpha_stall>1.4</alpha_stall>
      <cla>4.2500</cla>
      <cda>0.10</cda>
      <cma>0.00</cma>
      <cla_stall>-0.025</cla_stall>
      <cda_stall>0.0</cda_stall>
      <cma_stall>0.0</cma_stall>
      <area>0.002</area>
      <air_density>1.2041</air_density>
      <cp>-0.084 0 0</cp>
      <forward>0 1 0</forward>
      <upward>0 0 1</upward>
      <link_name>wasp::rotor_5</link_name>
    </plugin>
  </gazebo>
  <gazebo>
    <plugin filename="libArduPilotPlugin.so" name="arducopter_plugin">
      <fdm_addr>127.0.0.1</fdm_addr>
      <fdm_port_in>9002</fdm_port_in>
      <fdm_port_out>9003</fdm_port_out>
      <!--
            Require by APM :
            Only change model and gazebo from XYZ to XY-Z coordinates
        -->
      <modelXYZToAirplaneXForwardZDown>0 0 0 3.141593 0 0</modelXYZToAirplaneXForwardZDown>
      <gazeboXYZToNED>0 0 0 3.141593 0 0</gazeboXYZToNED>
      <imuName>wasp::wasp/imu_link::imu_sensor</imuName>
      <connectionTimeoutMaxCount>5</connectionTimeoutMaxCount>
      <control channel="0">
        <type>VELOCITY</type>
        <offset>0</offset>
        <p_gain>0.20</p_gain>
        <i_gain>0</i_gain>
        <d_gain>0</d_gain>
        <i_max>0</i_max>
        <i_min>0</i_min>
        <cmd_max>2.5</cmd_max>
        <cmd_min>-2.5</cmd_min>
        <jointName>wasp::rotor_0_joint</jointName>
        <multiplier>920</multiplier>
        <controlVelocitySlowdownSim>1</controlVelocitySlowdownSim>
      </control>
      <control channel="1">
        <type>VELOCITY</type>
        <offset>0</offset>
        <p_gain>0.20</p_gain>
        <i_gain>0</i_gain>
        <d_gain>0</d_gain>
        <i_max>0</i_max>
        <i_min>0</i_min>
        <cmd_max>2.5</cmd_max>
        <cmd_min>-2.5</cmd_min>
        <jointName>wasp::rotor_1_joint</jointName>
        <multiplier>-920</multiplier>
        <controlVelocitySlowdownSim>1</controlVelocitySlowdownSim>
      </control>
      <control channel="2">
        <type>VELOCITY</type>
        <offset>0</offset>
        <p_gain>0.20</p_gain>
        <i_gain>0</i_gain>
        <d_gain>0</d_gain>
        <i_max>0</i_max>
        <i_min>0</i_min>
        <cmd_max>2.5</cmd_max>
        <cmd_min>-2.5</cmd_min>
        <jointName>wasp::rotor_2_joint</jointName>
        <multiplier>920</multiplier>
        <controlVelocitySlowdownSim>1</controlVelocitySlowdownSim>
      </control>
      <control channel="3">
        <type>VELOCITY</type>
        <offset>0</offset>
        <p_gain>0.20</p_gain>
        <i_gain>0</i_gain>
        <d_gain>0</d_gain>
        <i_max>0</i_max>
        <i_min>0</i_min>
        <cmd_max>2.5</cmd_max>
        <cmd_min>-2.5</cmd_min>
        <jointName>wasp::rotor_3_joint</jointName>
        <multiplier>-920</multiplier>
        <controlVelocitySlowdownSim>1</controlVelocitySlowdownSim>
      </control>
      <control channel="4">
        <type>VELOCITY</type>
        <offset>0</offset>
        <p_gain>0.20</p_gain>
        <i_gain>0</i_gain>
        <d_gain>0</d_gain>
        <i_max>0</i_max>
        <i_min>0</i_min>
        <cmd_max>2.5</cmd_max>
        <cmd_min>-2.5</cmd_min>
        <jointName>wasp::rotor_4_joint</jointName>
        <multiplier>920</multiplier>
        <controlVelocitySlowdownSim>1</controlVelocitySlowdownSim>
      </control>
      <control channel="5">
        <type>VELOCITY</type>
        <offset>0</offset>
        <p_gain>0.20</p_gain>
        <i_gain>0</i_gain>
        <d_gain>0</d_gain>
        <i_max>0</i_max>
        <i_min>0</i_min>
        <cmd_max>2.5</cmd_max>
        <cmd_min>-2.5</cmd_min>
        <jointName>wasp::rotor_5_joint</jointName>
        <multiplier>-920</multiplier>
        <controlVelocitySlowdownSim>1</controlVelocitySlowdownSim>
      </control>
    </plugin>
  </gazebo>
  <!--<xacro:include filename="$(find realsense2_description)/urdf/_d435.urdf.xacro" />
  <xacro:sensor_d435 name="camera" topics_ns="camera" parent="base_link" publish_pointcloud="true">
    <origin xyz="0 -0.118 -0.074" rpy="0 ${pi/4} ${-pi/2}" />
  </xacro:sensor_d435>-->
  

  wasp

</robot>

