<?xml version='1.0'?>
<sdf version='1.6'>
  <model name='wasp'>
    <link name='base_link'>
      <pose frame=''>0 0 0 0 -0 0</pose>
      <inertial>
        <pose frame=''>0.004561 -0.033058 -0.053951 0 -0 0</pose>
        <mass>2.164</mass>
        <inertia>
          <ixx>0.0250036</ixx>
          <ixy>0.000925619</ixy>
          <ixz>0.00011064</ixz>
          <iyy>0.0201038</iyy>
          <iyz>-0.000800919</iyz>
          <izz>0.0132168</izz>
        </inertia>
      </inertial>
      <collision name='base_link_fixed_joint_lump__lander_collision'>
        <pose frame=''>0 0 -0.08 0 -0 0</pose>
        <geometry>
          <box>
            <size>0.3 0.2 0.16</size>
          </box>
        </geometry>
      </collision>
      <collision name='base_link_fixed_joint_lump__camera_link_collision_1'>
        <pose frame=''>0 -0.126839 -0.065161 0 0.785398 -1.5708</pose>
        <geometry>
          <box>
            <size>0.02505 0.09 0.025</size>
          </box>
        </geometry>
        <surface>
          <contact>
            <ode>
              <kp>1e+13</kp>
              <kd>1</kd>
            </ode>
          </contact>
          <friction>
            <ode>
              <mu2>1</mu2>
              <fdir1>0 0 0</fdir1>
            </ode>
          </friction>
        </surface>
      </collision>
      <visual name='base_link_visual'>
        <pose frame=''>0 0 0 0 -0 0</pose>
        <geometry>
          <mesh>
            <scale>1 1 1</scale>
            <uri>model://wasp_gazebo/meshes/wasp_core.dae</uri>
          </mesh>
        </geometry>
        <material>
          <script>
            <uri>__default__</uri>
            <name>__default__</name>
          </script>
        </material>
      </visual>
      <visual name='base_link_fixed_joint_lump__arm_0_visual_1'>
        <pose frame=''>0.075 0 0.0125 0 -0 1.5708</pose>
        <geometry>
          <mesh>
            <scale>1 1 1</scale>
            <uri>model://wasp_gazebo/meshes/wasp_arm.dae</uri>
          </mesh>
        </geometry>
      </visual>
      <visual name='base_link_fixed_joint_lump__motor_0_visual_2'>
        <pose frame=''>0.277 0 0.0125 0 -0 0</pose>
        <geometry>
          <mesh>
            <scale>1 1 1</scale>
            <uri>model://wasp_gazebo/meshes/wasp_motor.dae</uri>
          </mesh>
        </geometry>
      </visual>
      <visual name='base_link_fixed_joint_lump__arm_1_visual_3'>
        <pose frame=''>-0.075 0 0.0125 0 -0 -1.5708</pose>
        <geometry>
          <mesh>
            <scale>1 1 1</scale>
            <uri>model://wasp_gazebo/meshes/wasp_arm.dae</uri>
          </mesh>
        </geometry>
      </visual>
      <visual name='base_link_fixed_joint_lump__motor_1_visual_4'>
        <pose frame=''>-0.277 0 0.0125 0 -0 0</pose>
        <geometry>
          <mesh>
            <scale>1 1 1</scale>
            <uri>model://wasp_gazebo/meshes/wasp_motor.dae</uri>
          </mesh>
        </geometry>
      </visual>
      <visual name='base_link_fixed_joint_lump__arm_2_visual_5'>
        <pose frame=''>0.0375 0.064952 0.0125 0 -0 2.61799</pose>
        <geometry>
          <mesh>
            <scale>1 1 1</scale>
            <uri>model://wasp_gazebo/meshes/wasp_arm.dae</uri>
          </mesh>
        </geometry>
      </visual>
      <visual name='base_link_fixed_joint_lump__motor_2_visual_6'>
        <pose frame=''>0.1385 0.239889 0.0125 0 -0 0</pose>
        <geometry>
          <mesh>
            <scale>1 1 1</scale>
            <uri>model://wasp_gazebo/meshes/wasp_motor.dae</uri>
          </mesh>
        </geometry>
      </visual>
      <visual name='base_link_fixed_joint_lump__arm_3_visual_7'>
        <pose frame=''>-0.0375 -0.064952 0.0125 0 -0 -0.523599</pose>
        <geometry>
          <mesh>
            <scale>1 1 1</scale>
            <uri>model://wasp_gazebo/meshes/wasp_arm.dae</uri>
          </mesh>
        </geometry>
      </visual>
      <visual name='base_link_fixed_joint_lump__motor_3_visual_8'>
        <pose frame=''>-0.1385 -0.239889 0.0125 0 -0 0</pose>
        <geometry>
          <mesh>
            <scale>1 1 1</scale>
            <uri>model://wasp_gazebo/meshes/wasp_motor.dae</uri>
          </mesh>
        </geometry>
      </visual>
      <visual name='base_link_fixed_joint_lump__arm_4_visual_9'>
        <pose frame=''>-0.0375 0.064952 0.0125 0 -0 -2.61799</pose>
        <geometry>
          <mesh>
            <scale>1 1 1</scale>
            <uri>model://wasp_gazebo/meshes/wasp_arm.dae</uri>
          </mesh>
        </geometry>
      </visual>
      <visual name='base_link_fixed_joint_lump__motor_4_visual_10'>
        <pose frame=''>-0.1385 0.239889 0.0125 0 -0 0</pose>
        <geometry>
          <mesh>
            <scale>1 1 1</scale>
            <uri>model://wasp_gazebo/meshes/wasp_motor.dae</uri>
          </mesh>
        </geometry>
      </visual>
      <visual name='base_link_fixed_joint_lump__arm_5_visual_11'>
        <pose frame=''>0.0375 -0.064952 0.0125 0 -0 0.523599</pose>
        <geometry>
          <mesh>
            <scale>1 1 1</scale>
            <uri>model://wasp_gazebo/meshes/wasp_arm.dae</uri>
          </mesh>
        </geometry>
      </visual>
      <visual name='base_link_fixed_joint_lump__motor_5_visual_12'>
        <pose frame=''>0.1385 -0.239889 0.0125 0 -0 0</pose>
        <geometry>
          <mesh>
            <scale>1 1 1</scale>
            <uri>model://wasp_gazebo/meshes/wasp_motor.dae</uri>
          </mesh>
        </geometry>
      </visual>
      <visual name='base_link_fixed_joint_lump__leg_0_visual_13'>
        <pose frame=''>0.08044 0.044648 -0.063 0 -0 2.0775</pose>
        <geometry>
          <mesh>
            <scale>1 1 1</scale>
            <uri>model://wasp_gazebo/meshes/wasp_leg.dae</uri>
          </mesh>
        </geometry>
      </visual>
      <visual name='base_link_fixed_joint_lump__leg_1_visual_14'>
        <pose frame=''>0.08044 -0.044648 -0.063 0 -0 1.06409</pose>
        <geometry>
          <mesh>
            <scale>1 1 1</scale>
            <uri>model://wasp_gazebo/meshes/wasp_leg.dae</uri>
          </mesh>
        </geometry>
      </visual>
      <visual name='base_link_fixed_joint_lump__leg_2_visual_15'>
        <pose frame=''>-0.08044 -0.044648 -0.063 0 -0 -1.06409</pose>
        <geometry>
          <mesh>
            <scale>1 1 1</scale>
            <uri>model://wasp_gazebo/meshes/wasp_leg.dae</uri>
          </mesh>
        </geometry>
      </visual>
      <visual name='base_link_fixed_joint_lump__leg_3_visual_16'>
        <pose frame=''>-0.08044 0.044648 -0.063 0 -0 -2.0775</pose>
        <geometry>
          <mesh>
            <scale>1 1 1</scale>
            <uri>model://wasp_gazebo/meshes/wasp_leg.dae</uri>
          </mesh>
        </geometry>
      </visual>
      <visual name='base_link_fixed_joint_lump__rod_0_visual_17'>
        <pose frame=''>0.037 0 -0.036 0 -0 0</pose>
        <geometry>
          <mesh>
            <scale>1 1 1</scale>
            <uri>model://wasp_gazebo/meshes/wasp_support_rod.dae</uri>
          </mesh>
        </geometry>
      </visual>
      <visual name='base_link_fixed_joint_lump__cannister_0_visual_18'>
        <pose frame=''>0.063 -0.076 -0.074 -1.5708 0 0</pose>
        <geometry>
          <mesh>
            <scale>1 1 1</scale>
            <uri>model://wasp_gazebo/meshes/wasp_cannister.dae</uri>
          </mesh>
        </geometry>
      </visual>
      <visual name='base_link_fixed_joint_lump__rod_1_visual_19'>
        <pose frame=''>-0.037 0 -0.036 0 -0 0</pose>
        <geometry>
          <mesh>
            <scale>1 1 1</scale>
            <uri>model://wasp_gazebo/meshes/wasp_support_rod.dae</uri>
          </mesh>
        </geometry>
      </visual>
      <visual name='base_link_fixed_joint_lump__cannister_1_visual_20'>
        <pose frame=''>-0.063 -0.076 -0.074 -1.5708 0 0</pose>
        <geometry>
          <mesh>
            <scale>1 1 1</scale>
            <uri>model://wasp_gazebo/meshes/wasp_cannister.dae</uri>
          </mesh>
        </geometry>
      </visual>
      <visual name='base_link_fixed_joint_lump__camera_link_visual_21'>
        <pose frame=''>0 -0.137375 -0.075697 2.35619 0 0</pose>
        <geometry>
          <mesh>
            <scale>1 1 1</scale>
            <uri>model://realsense2_description/meshes/d435.dae</uri>
          </mesh>
        </geometry>
        <material>
          <script>
            <uri>__default__</uri>
            <name>__default__</name>
          </script>
        </material>
      </visual>
      <velocity_decay/>
      <self_collide>0</self_collide>
      <gravity>1</gravity>
      <velocity_decay/>
      <self_collide>0</self_collide>
      <enable_wind>0</enable_wind>
      <kinematic>0</kinematic>
      <gravity>1</gravity>
      <sensor name='cameracolor' type='camera'>
        <camera name='camera'>
          <horizontal_fov>1.21126</horizontal_fov>
          <image>
            <width>640</width>
            <height>480</height>
            <format>RGB_INT8</format>
          </image>
          <clip>
            <near>0.1</near>
            <far>100</far>
          </clip>
          <noise>
            <type>gaussian</type>
            <mean>0</mean>
            <stddev>0.007</stddev>
          </noise>
        </camera>
        <always_on>1</always_on>
        <update_rate>30</update_rate>
        <visualize>1</visualize>
        <pose frame=''>0.0175 -0.126839 -0.065161 0 0.785398 -1.5708</pose>
      </sensor>
      <sensor name='cameraired1' type='camera'>
        <camera name='camera'>
          <horizontal_fov>1.48702</horizontal_fov>
          <image>
            <width>1280</width>
            <height>720</height>
            <format>L_INT8</format>
          </image>
          <clip>
            <near>0.1</near>
            <far>100</far>
          </clip>
          <noise>
            <type>gaussian</type>
            <mean>0</mean>
            <stddev>0.05</stddev>
          </noise>
        </camera>
        <always_on>1</always_on>
        <update_rate>90</update_rate>
        <visualize>0</visualize>
        <pose frame=''>0.0175 -0.126839 -0.065161 0 0.785398 -1.5708</pose>
      </sensor>
      <sensor name='cameraired2' type='camera'>
        <camera name='camera'>
          <horizontal_fov>1.48702</horizontal_fov>
          <image>
            <width>1280</width>
            <height>720</height>
            <format>L_INT8</format>
          </image>
          <clip>
            <near>0.1</near>
            <far>100</far>
          </clip>
          <noise>
            <type>gaussian</type>
            <mean>0</mean>
            <stddev>0.05</stddev>
          </noise>
        </camera>
        <always_on>1</always_on>
        <update_rate>90</update_rate>
        <visualize>0</visualize>
        <pose frame=''>0.0175 -0.126839 -0.065161 0 0.785398 -1.5708</pose>
      </sensor>
      <sensor name='cameradepth' type='depth'>
        <camera name='camera'>
          <horizontal_fov>1.48702</horizontal_fov>
          <image>
            <width>1280</width>
            <height>720</height>
          </image>
          <clip>
            <near>0.1</near>
            <far>100</far>
          </clip>
          <noise>
            <type>gaussian</type>
            <mean>0</mean>
            <stddev>0.1</stddev>
          </noise>
        </camera>
        <always_on>1</always_on>
        <update_rate>90</update_rate>
        <visualize>0</visualize>
        <pose frame=''>0.0175 -0.126839 -0.065161 0 0.785398 -1.5708</pose>
      </sensor>
    </link>
    <link name='rotor_0'>
      <pose frame=''>0.277 0 0.042 0 -0 0</pose>
      <inertial>
        <pose frame=''>0 0 0 0 -0 0</pose>
        <mass>0.025</mass>
        <inertia>
          <ixx>9.75e-06</ixx>
          <ixy>0</ixy>
          <ixz>0</ixz>
          <iyy>0.0001667</iyy>
          <iyz>0</iyz>
          <izz>0.0001667</izz>
        </inertia>
      </inertial>
      <collision name='rotor_0_collision'>
        <pose frame=''>0 0 0 0 -0 0</pose>
        <geometry>
          <cylinder>
            <length>0.01</length>
            <radius>0.13</radius>
          </cylinder>
        </geometry>
        <surface>
          <contact>
            <ode/>
          </contact>
          <friction>
            <ode/>
          </friction>
        </surface>
      </collision>
      <visual name='rotor_0_visual'>
        <pose frame=''>0 0 0 0 -0 0</pose>
        <geometry>
          <mesh>
            <scale>1 1 1</scale>
            <uri>model://wasp_gazebo/meshes/wasp_prop_cw.dae</uri>
          </mesh>
        </geometry>
        <material>
          <script>
            <name>Gazebo/Red</name>
            <uri>file://media/materials/scripts/gazebo.material</uri>
          </script>
        </material>
      </visual>
      <gravity>1</gravity>
      <velocity_decay/>
      <self_collide>0</self_collide>
    </link>
    <joint name='rotor_0_joint' type='revolute'>
      <child>rotor_0</child>
      <parent>base_link</parent>
      <axis>
        <xyz>0 0 1</xyz>
        <limit>
          <lower>-1e+16</lower>
          <upper>1e+16</upper>
        </limit>
        <dynamics>
          <damping>0.004</damping>
          <friction>0</friction>
          <spring_reference>0</spring_reference>
          <spring_stiffness>0</spring_stiffness>
        </dynamics>
        <use_parent_model_frame>0</use_parent_model_frame>
      </axis>
    </joint>
    <link name='rotor_1'>
      <pose frame=''>-0.277 0 0.042 0 -0 0</pose>
      <inertial>
        <pose frame=''>0 0 0 0 -0 0</pose>
        <mass>0.025</mass>
        <inertia>
          <ixx>9.75e-06</ixx>
          <ixy>0</ixy>
          <ixz>0</ixz>
          <iyy>0.0001667</iyy>
          <iyz>0</iyz>
          <izz>0.0001667</izz>
        </inertia>
      </inertial>
      <collision name='rotor_1_collision'>
        <pose frame=''>0 0 0 0 -0 0</pose>
        <geometry>
          <cylinder>
            <length>0.01</length>
            <radius>0.13</radius>
          </cylinder>
        </geometry>
        <surface>
          <contact>
            <ode/>
          </contact>
          <friction>
            <ode/>
          </friction>
        </surface>
      </collision>
      <visual name='rotor_1_visual'>
        <pose frame=''>0 0 0 0 -0 0</pose>
        <geometry>
          <mesh>
            <scale>1 1 1</scale>
            <uri>model://wasp_gazebo/meshes/wasp_prop_ccw.dae</uri>
          </mesh>
        </geometry>
        <material>
          <script>
            <name>Gazebo/Blue</name>
            <uri>file://media/materials/scripts/gazebo.material</uri>
          </script>
        </material>
      </visual>
      <gravity>1</gravity>
      <velocity_decay/>
      <self_collide>0</self_collide>
    </link>
    <joint name='rotor_1_joint' type='revolute'>
      <child>rotor_1</child>
      <parent>base_link</parent>
      <axis>
        <xyz>0 0 1</xyz>
        <limit>
          <lower>-1e+16</lower>
          <upper>1e+16</upper>
        </limit>
        <dynamics>
          <damping>0.004</damping>
          <friction>0</friction>
          <spring_reference>0</spring_reference>
          <spring_stiffness>0</spring_stiffness>
        </dynamics>
        <use_parent_model_frame>0</use_parent_model_frame>
      </axis>
    </joint>
    <link name='rotor_2'>
      <pose frame=''>0.1385 0.239889 0.042 0 -0 0</pose>
      <inertial>
        <pose frame=''>0 0 0 0 -0 0</pose>
        <mass>0.025</mass>
        <inertia>
          <ixx>9.75e-06</ixx>
          <ixy>0</ixy>
          <ixz>0</ixz>
          <iyy>0.0001667</iyy>
          <iyz>0</iyz>
          <izz>0.0001667</izz>
        </inertia>
      </inertial>
      <collision name='rotor_2_collision'>
        <pose frame=''>0 0 0 0 -0 0</pose>
        <geometry>
          <cylinder>
            <length>0.01</length>
            <radius>0.13</radius>
          </cylinder>
        </geometry>
        <surface>
          <contact>
            <ode/>
          </contact>
          <friction>
            <ode/>
          </friction>
        </surface>
      </collision>
      <visual name='rotor_2_visual'>
        <pose frame=''>0 0 0 0 -0 0</pose>
        <geometry>
          <mesh>
            <scale>1 1 1</scale>
            <uri>model://wasp_gazebo/meshes/wasp_prop_cw.dae</uri>
          </mesh>
        </geometry>
        <material>
          <script>
            <name>Gazebo/Red</name>
            <uri>file://media/materials/scripts/gazebo.material</uri>
          </script>
        </material>
      </visual>
      <gravity>1</gravity>
      <velocity_decay/>
      <self_collide>0</self_collide>
    </link>
    <joint name='rotor_2_joint' type='revolute'>
      <child>rotor_2</child>
      <parent>base_link</parent>
      <axis>
        <xyz>0 0 1</xyz>
        <limit>
          <lower>-1e+16</lower>
          <upper>1e+16</upper>
        </limit>
        <dynamics>
          <damping>0.004</damping>
          <friction>0</friction>
          <spring_reference>0</spring_reference>
          <spring_stiffness>0</spring_stiffness>
        </dynamics>
        <use_parent_model_frame>0</use_parent_model_frame>
      </axis>
    </joint>
    <link name='rotor_3'>
      <pose frame=''>-0.1385 -0.239889 0.042 0 -0 0</pose>
      <inertial>
        <pose frame=''>0 0 0 0 -0 0</pose>
        <mass>0.025</mass>
        <inertia>
          <ixx>9.75e-06</ixx>
          <ixy>0</ixy>
          <ixz>0</ixz>
          <iyy>0.0001667</iyy>
          <iyz>0</iyz>
          <izz>0.0001667</izz>
        </inertia>
      </inertial>
      <collision name='rotor_3_collision'>
        <pose frame=''>0 0 0 0 -0 0</pose>
        <geometry>
          <cylinder>
            <length>0.01</length>
            <radius>0.13</radius>
          </cylinder>
        </geometry>
        <surface>
          <contact>
            <ode/>
          </contact>
          <friction>
            <ode/>
          </friction>
        </surface>
      </collision>
      <visual name='rotor_3_visual'>
        <pose frame=''>0 0 0 0 -0 0</pose>
        <geometry>
          <mesh>
            <scale>1 1 1</scale>
            <uri>model://wasp_gazebo/meshes/wasp_prop_ccw.dae</uri>
          </mesh>
        </geometry>
        <material>
          <script>
            <name>Gazebo/Blue</name>
            <uri>file://media/materials/scripts/gazebo.material</uri>
          </script>
        </material>
      </visual>
      <gravity>1</gravity>
      <velocity_decay/>
      <self_collide>0</self_collide>
    </link>
    <joint name='rotor_3_joint' type='revolute'>
      <child>rotor_3</child>
      <parent>base_link</parent>
      <axis>
        <xyz>0 0 1</xyz>
        <limit>
          <lower>-1e+16</lower>
          <upper>1e+16</upper>
        </limit>
        <dynamics>
          <damping>0.004</damping>
          <friction>0</friction>
          <spring_reference>0</spring_reference>
          <spring_stiffness>0</spring_stiffness>
        </dynamics>
        <use_parent_model_frame>0</use_parent_model_frame>
      </axis>
    </joint>
    <link name='rotor_4'>
      <pose frame=''>-0.1385 0.239889 0.042 0 -0 0</pose>
      <inertial>
        <pose frame=''>0 0 0 0 -0 0</pose>
        <mass>0.025</mass>
        <inertia>
          <ixx>9.75e-06</ixx>
          <ixy>0</ixy>
          <ixz>0</ixz>
          <iyy>0.0001667</iyy>
          <iyz>0</iyz>
          <izz>0.0001667</izz>
        </inertia>
      </inertial>
      <collision name='rotor_4_collision'>
        <pose frame=''>0 0 0 0 -0 0</pose>
        <geometry>
          <cylinder>
            <length>0.01</length>
            <radius>0.13</radius>
          </cylinder>
        </geometry>
        <surface>
          <contact>
            <ode/>
          </contact>
          <friction>
            <ode/>
          </friction>
        </surface>
      </collision>
      <visual name='rotor_4_visual'>
        <pose frame=''>0 0 0 0 -0 0</pose>
        <geometry>
          <mesh>
            <scale>1 1 1</scale>
            <uri>model://wasp_gazebo/meshes/wasp_prop_cw.dae</uri>
          </mesh>
        </geometry>
        <material>
          <script>
            <name>Gazebo/Red</name>
            <uri>file://media/materials/scripts/gazebo.material</uri>
          </script>
        </material>
      </visual>
      <gravity>1</gravity>
      <velocity_decay/>
      <self_collide>0</self_collide>
    </link>
    <joint name='rotor_4_joint' type='revolute'>
      <child>rotor_4</child>
      <parent>base_link</parent>
      <axis>
        <xyz>0 0 1</xyz>
        <limit>
          <lower>-1e+16</lower>
          <upper>1e+16</upper>
        </limit>
        <dynamics>
          <damping>0.004</damping>
          <friction>0</friction>
          <spring_reference>0</spring_reference>
          <spring_stiffness>0</spring_stiffness>
        </dynamics>
        <use_parent_model_frame>0</use_parent_model_frame>
      </axis>
    </joint>
    <link name='rotor_5'>
      <pose frame=''>0.1385 -0.239889 0.042 0 -0 0</pose>
      <inertial>
        <pose frame=''>0 0 0 0 -0 0</pose>
        <mass>0.025</mass>
        <inertia>
          <ixx>9.75e-06</ixx>
          <ixy>0</ixy>
          <ixz>0</ixz>
          <iyy>0.0001667</iyy>
          <iyz>0</iyz>
          <izz>0.0001667</izz>
        </inertia>
      </inertial>
      <collision name='rotor_5_collision'>
        <pose frame=''>0 0 0 0 -0 0</pose>
        <geometry>
          <cylinder>
            <length>0.01</length>
            <radius>0.13</radius>
          </cylinder>
        </geometry>
        <surface>
          <contact>
            <ode/>
          </contact>
          <friction>
            <ode/>
          </friction>
        </surface>
      </collision>
      <visual name='rotor_5_visual'>
        <pose frame=''>0 0 0 0 -0 0</pose>
        <geometry>
          <mesh>
            <scale>1 1 1</scale>
            <uri>model://wasp_gazebo/meshes/wasp_prop_ccw.dae</uri>
          </mesh>
        </geometry>
        <material>
          <script>
            <name>Gazebo/Blue</name>
            <uri>file://media/materials/scripts/gazebo.material</uri>
          </script>
        </material>
      </visual>
      <gravity>1</gravity>
      <velocity_decay/>
      <self_collide>0</self_collide>
    </link>
    <joint name='rotor_5_joint' type='revolute'>
      <child>rotor_5</child>
      <parent>base_link</parent>
      <axis>
        <xyz>0 0 1</xyz>
        <limit>
          <lower>-1e+16</lower>
          <upper>1e+16</upper>
        </limit>
        <dynamics>
          <damping>0.004</damping>
          <friction>0</friction>
          <spring_reference>0</spring_reference>
          <spring_stiffness>0</spring_stiffness>
        </dynamics>
        <use_parent_model_frame>0</use_parent_model_frame>
      </axis>
    </joint>
    <link name='wasp/ground_truth/odometry_sensorgt_link'>
      <pose frame=''>0 0 0 0 -0 0</pose>
      <inertial>
        <pose frame=''>0 0 0 0 -0 0</pose>
        <mass>0.15</mass>
        <inertia>
          <ixx>0.0001</ixx>
          <ixy>0</ixy>
          <ixz>0</ixz>
          <iyy>0.0002</iyy>
          <iyz>0</iyz>
          <izz>0.0002</izz>
        </inertia>
      </inertial>
      <self_collide>0</self_collide>
    </link>
    <joint name='wasp/ground_truth/odometry_sensorgt_joint' type='revolute'>
      <child>wasp/ground_truth/odometry_sensorgt_link</child>
      <parent>base_link</parent>
      <axis>
        <xyz>0 0 1</xyz>
        <limit>
          <lower>0</lower>
          <upper>0</upper>
          <effort>0</effort>
          <velocity>0</velocity>
        </limit>
        <dynamics>
          <damping>1</damping>
          <spring_reference>0</spring_reference>
          <spring_stiffness>0</spring_stiffness>
        </dynamics>
        <use_parent_model_frame>1</use_parent_model_frame>
      </axis>
      <physics>
        <ode>
          <implicit_spring_damper>1</implicit_spring_damper>
        </ode>
      </physics>
    </joint>
    <link name='wasp/imu_link'>
      <inertial>
        <pose frame=''>0 0 0 0 -0 0</pose>
        <mass>0.15</mass>
        <inertia>
          <ixx>1e-05</ixx>
          <ixy>0</ixy>
          <ixz>0</ixz>
          <iyy>1e-05</iyy>
          <iyz>0</iyz>
          <izz>1e-05</izz>
        </inertia>
      </inertial>
      <sensor name='imu_sensor' type='imu'>
        <pose frame=''>0 0 0 -3.14159 -0 0</pose>
        <always_on>1</always_on>
        <update_rate>1000</update_rate>
      </sensor>
      <self_collide>0</self_collide>
    </link>
    <joint name='wasp/imu_joint' type='revolute'>
      <child>wasp/imu_link</child>
      <parent>base_link</parent>
      <axis>
        <xyz>1 0 0</xyz>
        <limit>
          <lower>0</lower>
          <upper>0</upper>
          <effort>0</effort>
          <velocity>0</velocity>
        </limit>
        <dynamics>
          <spring_reference>0</spring_reference>
          <spring_stiffness>0</spring_stiffness>
        </dynamics>
        <use_parent_model_frame>1</use_parent_model_frame>
      </axis>
    </joint>
    <plugin name='rotor_0_blade_1' filename='libLiftDragPlugin.so'>
      <a0>0.3</a0>
      <alpha_stall>1.4</alpha_stall>
      <cla>4.2500</cla>
      <cda>0.10</cda>
      <cma>0.00</cma>
      <cla_stall>-0.025</cla_stall>
      <cda_stall>0.0</cda_stall>
      <cma_stall>0.0</cma_stall>
      <area>0.002</area>
      <air_density>1.2041</air_density>
      <cp>0.084 0 0</cp>
      <forward>0 1 0</forward>
      <upward>0 0 1</upward>
      <link_name>wasp::rotor_0</link_name>
    </plugin>
    <plugin name='rotor_0_blade_2' filename='libLiftDragPlugin.so'>
      <a0>0.3</a0>
      <alpha_stall>1.4</alpha_stall>
      <cla>4.2500</cla>
      <cda>0.10</cda>
      <cma>0.00</cma>
      <cla_stall>-0.025</cla_stall>
      <cda_stall>0.0</cda_stall>
      <cma_stall>0.0</cma_stall>
      <area>0.002</area>
      <air_density>1.2041</air_density>
      <cp>-0.084 0 0</cp>
      <forward>0 -1 0</forward>
      <upward>0 0 1</upward>
      <link_name>wasp::rotor_0</link_name>
    </plugin>
    <plugin name='rotor_1_blade_1' filename='libLiftDragPlugin.so'>
      <a0>0.3</a0>
      <alpha_stall>1.4</alpha_stall>
      <cla>4.2500</cla>
      <cda>0.10</cda>
      <cma>0.00</cma>
      <cla_stall>-0.025</cla_stall>
      <cda_stall>0.0</cda_stall>
      <cma_stall>0.0</cma_stall>
      <area>0.002</area>
      <air_density>1.2041</air_density>
      <cp>0.084 0 0</cp>
      <forward>0 -1 0</forward>
      <upward>0 0 1</upward>
      <link_name>wasp::rotor_1</link_name>
    </plugin>
    <plugin name='rotor_1_blade_2' filename='libLiftDragPlugin.so'>
      <a0>0.3</a0>
      <alpha_stall>1.4</alpha_stall>
      <cla>4.2500</cla>
      <cda>0.10</cda>
      <cma>0.00</cma>
      <cla_stall>-0.025</cla_stall>
      <cda_stall>0.0</cda_stall>
      <cma_stall>0.0</cma_stall>
      <area>0.002</area>
      <air_density>1.2041</air_density>
      <cp>-0.084 0 0</cp>
      <forward>0 1 0</forward>
      <upward>0 0 1</upward>
      <link_name>wasp::rotor_1</link_name>
    </plugin>
    <plugin name='rotor_2_blade_1' filename='libLiftDragPlugin.so'>
      <a0>0.3</a0>
      <alpha_stall>1.4</alpha_stall>
      <cla>4.2500</cla>
      <cda>0.10</cda>
      <cma>0.00</cma>
      <cla_stall>-0.025</cla_stall>
      <cda_stall>0.0</cda_stall>
      <cma_stall>0.0</cma_stall>
      <area>0.002</area>
      <air_density>1.2041</air_density>
      <cp>0.084 0 0</cp>
      <forward>0 1 0</forward>
      <upward>0 0 1</upward>
      <link_name>wasp::rotor_2</link_name>
    </plugin>
    <plugin name='rotor_2_blade_2' filename='libLiftDragPlugin.so'>
      <a0>0.3</a0>
      <alpha_stall>1.4</alpha_stall>
      <cla>4.2500</cla>
      <cda>0.10</cda>
      <cma>0.00</cma>
      <cla_stall>-0.025</cla_stall>
      <cda_stall>0.0</cda_stall>
      <cma_stall>0.0</cma_stall>
      <area>0.002</area>
      <air_density>1.2041</air_density>
      <cp>-0.084 0 0</cp>
      <forward>0 -1 0</forward>
      <upward>0 0 1</upward>
      <link_name>wasp::rotor_2</link_name>
    </plugin>
    <plugin name='rotor_3_blade_1' filename='libLiftDragPlugin.so'>
      <a0>0.3</a0>
      <alpha_stall>1.4</alpha_stall>
      <cla>4.2500</cla>
      <cda>0.10</cda>
      <cma>0.00</cma>
      <cla_stall>-0.025</cla_stall>
      <cda_stall>0.0</cda_stall>
      <cma_stall>0.0</cma_stall>
      <area>0.002</area>
      <air_density>1.2041</air_density>
      <cp>0.084 0 0</cp>
      <forward>0 -1 0</forward>
      <upward>0 0 1</upward>
      <link_name>wasp::rotor_3</link_name>
    </plugin>
    <plugin name='rotor_3_blade_2' filename='libLiftDragPlugin.so'>
      <a0>0.3</a0>
      <alpha_stall>1.4</alpha_stall>
      <cla>4.2500</cla>
      <cda>0.10</cda>
      <cma>0.00</cma>
      <cla_stall>-0.025</cla_stall>
      <cda_stall>0.0</cda_stall>
      <cma_stall>0.0</cma_stall>
      <area>0.002</area>
      <air_density>1.2041</air_density>
      <cp>-0.084 0 0</cp>
      <forward>0 1 0</forward>
      <upward>0 0 1</upward>
      <link_name>wasp::rotor_3</link_name>
    </plugin>
    <plugin name='rotor_4_blade_1' filename='libLiftDragPlugin.so'>
      <a0>0.3</a0>
      <alpha_stall>1.4</alpha_stall>
      <cla>4.2500</cla>
      <cda>0.10</cda>
      <cma>0.00</cma>
      <cla_stall>-0.025</cla_stall>
      <cda_stall>0.0</cda_stall>
      <cma_stall>0.0</cma_stall>
      <area>0.002</area>
      <air_density>1.2041</air_density>
      <cp>0.084 0 0</cp>
      <forward>0 1 0</forward>
      <upward>0 0 1</upward>
      <link_name>wasp::rotor_4</link_name>
    </plugin>
    <plugin name='rotor_4_blade_2' filename='libLiftDragPlugin.so'>
      <a0>0.3</a0>
      <alpha_stall>1.4</alpha_stall>
      <cla>4.2500</cla>
      <cda>0.10</cda>
      <cma>0.00</cma>
      <cla_stall>-0.025</cla_stall>
      <cda_stall>0.0</cda_stall>
      <cma_stall>0.0</cma_stall>
      <area>0.002</area>
      <air_density>1.2041</air_density>
      <cp>-0.084 0 0</cp>
      <forward>0 -1 0</forward>
      <upward>0 0 1</upward>
      <link_name>wasp::rotor_4</link_name>
    </plugin>
    <plugin name='rotor_5_blade_1' filename='libLiftDragPlugin.so'>
      <a0>0.3</a0>
      <alpha_stall>1.4</alpha_stall>
      <cla>4.2500</cla>
      <cda>0.10</cda>
      <cma>0.00</cma>
      <cla_stall>-0.025</cla_stall>
      <cda_stall>0.0</cda_stall>
      <cma_stall>0.0</cma_stall>
      <area>0.002</area>
      <air_density>1.2041</air_density>
      <cp>0.084 0 0</cp>
      <forward>0 -1 0</forward>
      <upward>0 0 1</upward>
      <link_name>wasp::rotor_5</link_name>
    </plugin>
    <plugin name='rotor_5_blade_2' filename='libLiftDragPlugin.so'>
      <a0>0.3</a0>
      <alpha_stall>1.4</alpha_stall>
      <cla>4.2500</cla>
      <cda>0.10</cda>
      <cma>0.00</cma>
      <cla_stall>-0.025</cla_stall>
      <cda_stall>0.0</cda_stall>
      <cma_stall>0.0</cma_stall>
      <area>0.002</area>
      <air_density>1.2041</air_density>
      <cp>-0.084 0 0</cp>
      <forward>0 1 0</forward>
      <upward>0 0 1</upward>
      <link_name>wasp::rotor_5</link_name>
    </plugin>
    <plugin name='arducopter_plugin' filename='libArduPilotPlugin.so'>
      <fdm_addr>127.0.0.1</fdm_addr>
      <fdm_port_in>9002</fdm_port_in>
      <fdm_port_out>9003</fdm_port_out>
      <modelXYZToAirplaneXForwardZDown>0 0 0 3.141593 0 0</modelXYZToAirplaneXForwardZDown>
      <gazeboXYZToNED>0 0 0 3.141593 0 0</gazeboXYZToNED>
      <imuName>wasp::wasp/imu_link::imu_sensor</imuName>
      <connectionTimeoutMaxCount>5</connectionTimeoutMaxCount>
      <control channel='0'>
        <type>VELOCITY</type>
        <offset>0</offset>
        <p_gain>0.20</p_gain>
        <i_gain>0</i_gain>
        <d_gain>0</d_gain>
        <i_max>0</i_max>
        <i_min>0</i_min>
        <cmd_max>2.5</cmd_max>
        <cmd_min>-2.5</cmd_min>
        <jointName>wasp::rotor_0_joint</jointName>
        <multiplier>920</multiplier>
        <controlVelocitySlowdownSim>1</controlVelocitySlowdownSim>
      </control>
      <control channel='1'>
        <type>VELOCITY</type>
        <offset>0</offset>
        <p_gain>0.20</p_gain>
        <i_gain>0</i_gain>
        <d_gain>0</d_gain>
        <i_max>0</i_max>
        <i_min>0</i_min>
        <cmd_max>2.5</cmd_max>
        <cmd_min>-2.5</cmd_min>
        <jointName>wasp::rotor_1_joint</jointName>
        <multiplier>-920</multiplier>
        <controlVelocitySlowdownSim>1</controlVelocitySlowdownSim>
      </control>
      <control channel='2'>
        <type>VELOCITY</type>
        <offset>0</offset>
        <p_gain>0.20</p_gain>
        <i_gain>0</i_gain>
        <d_gain>0</d_gain>
        <i_max>0</i_max>
        <i_min>0</i_min>
        <cmd_max>2.5</cmd_max>
        <cmd_min>-2.5</cmd_min>
        <jointName>wasp::rotor_2_joint</jointName>
        <multiplier>920</multiplier>
        <controlVelocitySlowdownSim>1</controlVelocitySlowdownSim>
      </control>
      <control channel='3'>
        <type>VELOCITY</type>
        <offset>0</offset>
        <p_gain>0.20</p_gain>
        <i_gain>0</i_gain>
        <d_gain>0</d_gain>
        <i_max>0</i_max>
        <i_min>0</i_min>
        <cmd_max>2.5</cmd_max>
        <cmd_min>-2.5</cmd_min>
        <jointName>wasp::rotor_3_joint</jointName>
        <multiplier>-920</multiplier>
        <controlVelocitySlowdownSim>1</controlVelocitySlowdownSim>
      </control>
      <control channel='4'>
        <type>VELOCITY</type>
        <offset>0</offset>
        <p_gain>0.20</p_gain>
        <i_gain>0</i_gain>
        <d_gain>0</d_gain>
        <i_max>0</i_max>
        <i_min>0</i_min>
        <cmd_max>2.5</cmd_max>
        <cmd_min>-2.5</cmd_min>
        <jointName>wasp::rotor_4_joint</jointName>
        <multiplier>920</multiplier>
        <controlVelocitySlowdownSim>1</controlVelocitySlowdownSim>
      </control>
      <control channel='5'>
        <type>VELOCITY</type>
        <offset>0</offset>
        <p_gain>0.20</p_gain>
        <i_gain>0</i_gain>
        <d_gain>0</d_gain>
        <i_max>0</i_max>
        <i_min>0</i_min>
        <cmd_max>2.5</cmd_max>
        <cmd_min>-2.5</cmd_min>
        <jointName>wasp::rotor_5_joint</jointName>
        <multiplier>-920</multiplier>
        <controlVelocitySlowdownSim>1</controlVelocitySlowdownSim>
      </control>
    </plugin>
    <static>0</static>
    <plugin name='camera' filename='librealsense_gazebo_plugin.so'>
      <prefix>camera</prefix>
      <depthUpdateRate>30.0</depthUpdateRate>
      <colorUpdateRate>30.0</colorUpdateRate>
      <infraredUpdateRate>30.0</infraredUpdateRate>
      <depthTopicName>depth/image_raw</depthTopicName>
      <depthCameraInfoTopicName>depth/camera_info</depthCameraInfoTopicName>
      <colorTopicName>color/image_raw</colorTopicName>
      <colorCameraInfoTopicName>color/camera_info</colorCameraInfoTopicName>
      <infrared1TopicName>infra1/image_raw</infrared1TopicName>
      <infrared1CameraInfoTopicName>infra1/camera_info</infrared1CameraInfoTopicName>
      <infrared2TopicName>infra2/image_raw</infrared2TopicName>
      <infrared2CameraInfoTopicName>infra2/camera_info</infrared2CameraInfoTopicName>
      <colorOpticalframeName>camera_color_optical_frame</colorOpticalframeName>
      <depthOpticalframeName>camera_depth_optical_frame</depthOpticalframeName>
      <infrared1OpticalframeName>camera_left_ir_optical_frame</infrared1OpticalframeName>
      <infrared2OpticalframeName>camera_right_ir_optical_frame</infrared2OpticalframeName>
      <rangeMinDepth>0.2</rangeMinDepth>
      <rangeMaxDepth>10.0</rangeMaxDepth>
      <pointCloud>1</pointCloud>
      <pointCloudTopicName>depth/color/points</pointCloudTopicName>
      <pointCloudCutoff>0.25</pointCloudCutoff>
      <pointCloudCutoffMax>9.0</pointCloudCutoffMax>
    </plugin>
  </model>
</sdf>
