<?xml version="1.0" encoding="utf-8"?>
<!-- =================================================================================== -->
<!-- |    This document was autogenerated by xacro from drone.urdf.xacro               | -->
<!-- |    EDITING THIS FILE BY HAND IS NOT RECOMMENDED                                 | -->
<!-- =================================================================================== -->
<robot name="wasp">
  <material name="black">
    <color rgba="0.0 0.0 0.0 1.0"/>
  </material>
  <material name="blue">
    <color rgba="0.0 0.0 0.8 1.0"/>
  </material>
  <material name="green">
    <color rgba="0.0 0.8 0.0 1.0"/>
  </material>
  <material name="grey">
    <color rgba="0.2 0.2 0.2 1.0"/>
  </material>
  <material name="orange">
    <color rgba="1.0 0.423529411765 0.0392156862745 1.0"/>
  </material>
  <material name="brown">
    <color rgba="0.870588235294 0.811764705882 0.764705882353 1.0"/>
  </material>
  <material name="red">
    <color rgba="0.8 0.0 0.0 1.0"/>
  </material>
  <material name="white">
    <color rgba="1.0 1.0 1.0 1.0"/>
  </material>
  <link name="base_link">
    <inertial>
      <origin rpy="0 0 0" xyz="0.00158 0.00084 -0.06501"/>
      <mass value="3.67"/>
      <inertia ixx="0.03" ixy="0.0" ixz="0.0" iyy="0.032" iyz="0.0" izz="0.0050"/>
    </inertial>
    <!--
    <collision name="frame">
      <origin xyz="0 0 0.02" rpy="0 0 0"/>
      <geometry>
        <cylinder length="0.04" radius="0.3"/>
      </geometry>
    </collision>
    <collision name="rollcage">
      <origin xyz="0 0 0.066" rpy="0 0 0"/>
      <geometry>
        <cylinder length="0.06" radius="0.10"/>
      </geometry>
    </collision>
    -->
    <collision name="lander">
      <origin rpy="0 0 0" xyz="0 0 -0.22"/>
      <geometry>
        <box size="0.3 0.2 0.16"/>
      </geometry>
    </collision>
    <visual>
      <origin rpy="0 0 0" xyz="0 0 0"/>
      <geometry>
        <mesh filename="package://wasp_gazebo/meshes/WASP_CORE.dae"/>
      </geometry>
    </visual>
    <visual>
      <origin rpy="0 0 0" xyz="0 0 0"/>
      <geometry>
        <mesh filename="package://wasp_gazebo/meshes/WASP_TOP.dae"/>
      </geometry>
    </visual>
    <visual>
      <origin rpy="0 0 0" xyz="0 0 -0.002"/>
      <geometry>
        <mesh filename="package://wasp_gazebo/meshes/WASP_CAGE.dae"/>
      </geometry>
    </visual>
    <visual>
      <origin rpy="0 0 0" xyz="0 0 -0.14"/>
      <geometry>
        <mesh filename="package://wasp_gazebo/meshes/WASP_EXTRUDER_MOUNT.dae"/>
      </geometry>
    </visual>
    <visual name="arm_0">
      <origin rpy="0 0 1.57079632679" xyz="0.075 0.0 -0.0062"/>
      <geometry>
        <mesh filename="package://wasp_gazebo/meshes/WASP_ARM.dae"/>
      </geometry>
      <material name="black"/>
    </visual>
    <visual name="motor_0">
      <origin rpy="0 0 0" xyz="0.2794 0.0 -0.0062"/>
      <geometry>
        <mesh filename="package://wasp_gazebo/meshes/WASP_MOTOR.dae"/>
      </geometry>
      <material name="black"/>
    </visual>
    <visual name="arm_1">
      <origin rpy="0 0 4.71238898038" xyz="-0.075 9.18485099361e-18 -0.0062"/>
      <geometry>
        <mesh filename="package://wasp_gazebo/meshes/WASP_ARM.dae"/>
      </geometry>
      <material name="black"/>
    </visual>
    <visual name="motor_1">
      <origin rpy="0 0 0" xyz="-0.2794 3.42166315682e-17 -0.0062"/>
      <geometry>
        <mesh filename="package://wasp_gazebo/meshes/WASP_MOTOR.dae"/>
      </geometry>
      <material name="black"/>
    </visual>
    <visual name="arm_2">
      <origin rpy="0 0 2.61799387799" xyz="0.0375 0.0649519052838 -0.0062"/>
      <geometry>
        <mesh filename="package://wasp_gazebo/meshes/WASP_ARM.dae"/>
      </geometry>
      <material name="black"/>
    </visual>
    <visual name="motor_2">
      <origin rpy="0 0 0" xyz="0.1397 0.241967497817 -0.0062"/>
      <geometry>
        <mesh filename="package://wasp_gazebo/meshes/WASP_MOTOR.dae"/>
      </geometry>
      <material name="black"/>
    </visual>
    <visual name="arm_3">
      <origin rpy="0 0 5.75958653158" xyz="-0.0375 -0.0649519052838 -0.0062"/>
      <geometry>
        <mesh filename="package://wasp_gazebo/meshes/WASP_ARM.dae"/>
      </geometry>
      <material name="black"/>
    </visual>
    <visual name="motor_3">
      <origin rpy="0 0 0" xyz="-0.1397 -0.241967497817 -0.0062"/>
      <geometry>
        <mesh filename="package://wasp_gazebo/meshes/WASP_MOTOR.dae"/>
      </geometry>
      <material name="black"/>
    </visual>
    <visual name="arm_4">
      <origin rpy="0 0 3.66519142919" xyz="-0.0375 0.0649519052838 -0.0062"/>
      <geometry>
        <mesh filename="package://wasp_gazebo/meshes/WASP_ARM.dae"/>
      </geometry>
      <material name="black"/>
    </visual>
    <visual name="motor_4">
      <origin rpy="0 0 0" xyz="-0.1397 0.241967497817 -0.0062"/>
      <geometry>
        <mesh filename="package://wasp_gazebo/meshes/WASP_MOTOR.dae"/>
      </geometry>
      <material name="black"/>
    </visual>
    <visual name="arm_5">
      <origin rpy="0 0 6.80678408278" xyz="0.0375 -0.0649519052838 -0.0062"/>
      <geometry>
        <mesh filename="package://wasp_gazebo/meshes/WASP_ARM.dae"/>
      </geometry>
      <material name="black"/>
    </visual>
    <visual name="motor_5">
      <origin rpy="0 0 0" xyz="0.1397 -0.241967497817 -0.0062"/>
      <geometry>
        <mesh filename="package://wasp_gazebo/meshes/WASP_MOTOR.dae"/>
      </geometry>
      <material name="black"/>
    </visual>
    <visual name="leg_0">
      <origin rpy="0 0 2.10326965791" xyz="0.0637550020231 0.0375672692251 -0.206"/>
      <geometry>
        <mesh filename="package://wasp_gazebo/meshes/WASP_LEG.dae"/>
      </geometry>
      <material name="black"/>
    </visual>
    <visual name="leg_1">
      <origin rpy="0 0 1.03832299568" xyz="0.0637550020231 -0.0375672692251 -0.206"/>
      <geometry>
        <mesh filename="package://wasp_gazebo/meshes/WASP_LEG.dae"/>
      </geometry>
      <material name="black"/>
    </visual>
    <visual name="leg_2">
      <origin rpy="0 0 5.2448623115" xyz="-0.0637550020231 -0.0375672692251 -0.206"/>
      <geometry>
        <mesh filename="package://wasp_gazebo/meshes/WASP_LEG.dae"/>
      </geometry>
      <material name="black"/>
    </visual>
    <visual name="leg_3">
      <origin rpy="0 0 4.17991564927" xyz="-0.0637550020231 0.0375672692251 -0.206"/>
      <geometry>
        <mesh filename="package://wasp_gazebo/meshes/WASP_LEG.dae"/>
      </geometry>
      <material name="black"/>
    </visual>
    <visual name="cannister_0">
      <origin rpy="-1.57079632679 0 0" xyz="0.08 -0.076 -0.112"/>
      <geometry>
        <mesh filename="package://wasp_gazebo/meshes/WASP_CANNISTER.dae"/>
      </geometry>
      <material name="white"/>
    </visual>
    <visual name="cannister_1">
      <origin rpy="-1.57079632679 0 0" xyz="-0.08 -0.076 -0.112"/>
      <geometry>
        <mesh filename="package://wasp_gazebo/meshes/WASP_CANNISTER.dae"/>
      </geometry>
      <material name="white"/>
    </visual>
  </link>
  <link name="nozzle_link">
    <inertial>
      <origin rpy="0 0 0" xyz="0 0 0"/>
      <mass value="0.01"/>
      <inertia ixx="0.0001" ixy="0.0" ixz="0.0" iyy="0.0001" iyz="0.0" izz="0.0001"/>
    </inertial>
    <visual>
      <origin rpy="0 0 1.57079632679" xyz="0 0 0"/>
      <geometry>
        <mesh filename="package://wasp_gazebo/meshes/WASP_NOZZLE.dae"/>
      </geometry>
    </visual>
  </link>
  <joint name="nozzle_joint" type="fixed">
    <parent link="base_link"/>
    <child link="nozzle_link"/>
    <origin rpy="0 0 0" xyz="-0.059 0.023 -0.286"/>
  </joint>
  <joint name="rotor_0_joint" type="continuous">
    <parent link="base_link"/>
    <child link="rotor_0"/>
    <origin rpy="0 0 0" xyz="0.2794 0.0 0.029"/>
    <axis xyz="0 0 1"/>
    <dynamics damping="0.004"/>
  </joint>
  <link name="rotor_0">
    <collision>
      <origin rpy="0 0 0" xyz="0 0 0"/>
      <geometry>
        <cylinder length="0.01" radius="0.13"/>
      </geometry>
    </collision>
    <inertial>
      <origin rpy="0 0 0" xyz="0 0 0"/>
      <mass value="0.025"/>
      <inertia ixx="9.750e-06" ixy="0.0" ixz="0.0" iyy="166.7e-06" iyz="0.0" izz="166.7e-06"/>
    </inertial>
    <visual>
      <origin rpy="0 0 0" xyz="0 0 0"/>
      <geometry>
        <mesh filename="package://wasp_gazebo/meshes/WASP_PROP_CW.dae"/>
      </geometry>
      <material name="blue"/>
    </visual>
  </link>
  <joint name="rotor_1_joint" type="continuous">
    <parent link="base_link"/>
    <child link="rotor_1"/>
    <origin rpy="0 0 0" xyz="-0.2794 3.42166315682e-17 0.029"/>
    <axis xyz="0 0 1"/>
    <dynamics damping="0.004"/>
  </joint>
  <link name="rotor_1">
    <collision>
      <origin rpy="0 0 0" xyz="0 0 0"/>
      <geometry>
        <cylinder length="0.01" radius="0.13"/>
      </geometry>
    </collision>
    <inertial>
      <origin rpy="0 0 0" xyz="0 0 0"/>
      <mass value="0.025"/>
      <inertia ixx="9.750e-06" ixy="0.0" ixz="0.0" iyy="166.7e-06" iyz="0.0" izz="166.7e-06"/>
    </inertial>
    <visual>
      <origin rpy="0 0 0" xyz="0 0 0"/>
      <geometry>
        <mesh filename="package://wasp_gazebo/meshes/WASP_PROP_CCW.dae"/>
      </geometry>
      <material name="red"/>
    </visual>
  </link>
  <joint name="rotor_2_joint" type="continuous">
    <parent link="base_link"/>
    <child link="rotor_2"/>
    <origin rpy="0 0 0" xyz="0.1397 0.241967497817 0.029"/>
    <axis xyz="0 0 1"/>
    <dynamics damping="0.004"/>
  </joint>
  <link name="rotor_2">
    <collision>
      <origin rpy="0 0 0" xyz="0 0 0"/>
      <geometry>
        <cylinder length="0.01" radius="0.13"/>
      </geometry>
    </collision>
    <inertial>
      <origin rpy="0 0 0" xyz="0 0 0"/>
      <mass value="0.025"/>
      <inertia ixx="9.750e-06" ixy="0.0" ixz="0.0" iyy="166.7e-06" iyz="0.0" izz="166.7e-06"/>
    </inertial>
    <visual>
      <origin rpy="0 0 0" xyz="0 0 0"/>
      <geometry>
        <mesh filename="package://wasp_gazebo/meshes/WASP_PROP_CCW.dae"/>
      </geometry>
      <material name="red"/>
    </visual>
  </link>
  <joint name="rotor_3_joint" type="continuous">
    <parent link="base_link"/>
    <child link="rotor_3"/>
    <origin rpy="0 0 0" xyz="-0.1397 -0.241967497817 0.029"/>
    <axis xyz="0 0 1"/>
    <dynamics damping="0.004"/>
  </joint>
  <link name="rotor_3">
    <collision>
      <origin rpy="0 0 0" xyz="0 0 0"/>
      <geometry>
        <cylinder length="0.01" radius="0.13"/>
      </geometry>
    </collision>
    <inertial>
      <origin rpy="0 0 0" xyz="0 0 0"/>
      <mass value="0.025"/>
      <inertia ixx="9.750e-06" ixy="0.0" ixz="0.0" iyy="166.7e-06" iyz="0.0" izz="166.7e-06"/>
    </inertial>
    <visual>
      <origin rpy="0 0 0" xyz="0 0 0"/>
      <geometry>
        <mesh filename="package://wasp_gazebo/meshes/WASP_PROP_CW.dae"/>
      </geometry>
      <material name="blue"/>
    </visual>
  </link>
  <joint name="rotor_4_joint" type="continuous">
    <parent link="base_link"/>
    <child link="rotor_4"/>
    <origin rpy="0 0 0" xyz="-0.1397 0.241967497817 0.029"/>
    <axis xyz="0 0 1"/>
    <dynamics damping="0.004"/>
  </joint>
  <link name="rotor_4">
    <collision>
      <origin rpy="0 0 0" xyz="0 0 0"/>
      <geometry>
        <cylinder length="0.01" radius="0.13"/>
      </geometry>
    </collision>
    <inertial>
      <origin rpy="0 0 0" xyz="0 0 0"/>
      <mass value="0.025"/>
      <inertia ixx="9.750e-06" ixy="0.0" ixz="0.0" iyy="166.7e-06" iyz="0.0" izz="166.7e-06"/>
    </inertial>
    <visual>
      <origin rpy="0 0 0" xyz="0 0 0"/>
      <geometry>
        <mesh filename="package://wasp_gazebo/meshes/WASP_PROP_CW.dae"/>
      </geometry>
      <material name="blue"/>
    </visual>
  </link>
  <joint name="rotor_5_joint" type="continuous">
    <parent link="base_link"/>
    <child link="rotor_5"/>
    <origin rpy="0 0 0" xyz="0.1397 -0.241967497817 0.029"/>
    <axis xyz="0 0 1"/>
    <dynamics damping="0.004"/>
  </joint>
  <link name="rotor_5">
    <collision>
      <origin rpy="0 0 0" xyz="0 0 0"/>
      <geometry>
        <cylinder length="0.01" radius="0.13"/>
      </geometry>
    </collision>
    <inertial>
      <origin rpy="0 0 0" xyz="0 0 0"/>
      <mass value="0.025"/>
      <inertia ixx="9.750e-06" ixy="0.0" ixz="0.0" iyy="166.7e-06" iyz="0.0" izz="166.7e-06"/>
    </inertial>
    <visual>
      <origin rpy="0 0 0" xyz="0 0 0"/>
      <geometry>
        <mesh filename="package://wasp_gazebo/meshes/WASP_PROP_CCW.dae"/>
      </geometry>
      <material name="red"/>
    </visual>
  </link>
  <gazebo reference="base_link">
    <selfCollide>false</selfCollide>
    <maxVel>100.0</maxVel>
    <minDepth>0.001</minDepth>
    <mu1 value="200.0"/>
    <mu2 value="100.0"/>
    <kp value="10000000.0"/>
    <kd value="1.0"/>
    <!--     <material>Gazebo/Black</material> -->
  </gazebo>
  <gazebo reference="rotor_0">
    <material>
      Gazebo/Blue
    </material>
  </gazebo>
  <gazebo reference="rotor_1">
    <material>
      Gazebo/Red
    </material>
  </gazebo>
  <gazebo reference="rotor_2">
    <material>
      Gazebo/Red
    </material>
  </gazebo>
  <gazebo reference="rotor_3">
    <material>
      Gazebo/Blue
    </material>
  </gazebo>
  <gazebo reference="rotor_4">
    <material>
      Gazebo/Blue
    </material>
  </gazebo>
  <gazebo reference="rotor_5">
    <material>
      Gazebo/Red
    </material>
  </gazebo>
  <gazebo reference="nozzle_link">
    <visual name="extruder">
      <pose frame="">0 0 -0.05 0 0 0</pose>
      <geometry>
        <sphere>
          <radius>0.01</radius>
        </sphere>
      </geometry>
      <plugin filename="libwasp_gazebo.so" name="foamer">
        <particleSize>0.02</particleSize>
      </plugin>
    </visual>
    <material>Gazebo/White</material>
  </gazebo>
  <gazebo>
    <link name="wasp/imu_link">
      <pose>0 0 0 0 0 0</pose>
      <inertial>
        <pose>0 0 0 0 0 0</pose>
        <mass>0.015</mass>
        <inertia>
          <ixx>1e-05</ixx>
          <ixy>0</ixy>
          <ixz>0</ixz>
          <iyy>1e-05</iyy>
          <iyz>0</iyz>
          <izz>1e-05</izz>
        </inertia>
      </inertial>
    </link>
    <joint name="wasp/imu_joint" type="revolute">
      <child>wasp/imu_link</child>
      <parent>base_link</parent>
      <axis>
        <xyz>1 0 0</xyz>
        <limit>
          <lower>0</lower>
          <upper>0</upper>
          <effort>0</effort>
          <velocity>0</velocity>
        </limit>
        <dynamics>
          <spring_reference>0</spring_reference>
          <spring_stiffness>0</spring_stiffness>
        </dynamics>
        <use_parent_model_frame>1</use_parent_model_frame>
      </axis>
    </joint>
    <!-- Comment this section to disable GPS -->
    <!--    <include>
      <uri>model://gps</uri>
      <pose>0 0 0 0 0 0</pose>
      <name>gps</name>
    </include>
    <joint name='gps_joint' type='fixed'>
      <child>gps::link</child>
      <parent>base_link</parent>
    </joint>-->
    <plugin filename="libgazebo_multirotor_base_plugin.so" name="rosbag">
      <robotNamespace/>
      <linkName>base_link</linkName>
      <rotorVelocitySlowdownSim>10</rotorVelocitySlowdownSim>
    </plugin>
    <plugin filename="libgazebo_motor_model.so" name="rotor_plugin_0">
      <robotNamespace/>
      <jointName>rotor_0_joint</jointName>
      <linkName>rotor_0</linkName>
      <turningDirection>
        cw
      </turningDirection>
      <timeConstantUp>0.0125</timeConstantUp>
      <timeConstantDown>0.025</timeConstantDown>
      <maxRotVelocity>1500</maxRotVelocity>
      <motorConstant>8.54858e-06</motorConstant>
      <momentConstant>0.06</momentConstant>
      <commandSubTopic>/gazebo/command/motor_speed</commandSubTopic>
      <motorNumber>5</motorNumber>
      <rotorDragCoefficient>0.000806428</rotorDragCoefficient>
      <rollingMomentCoefficient>1e-06</rollingMomentCoefficient>
      <motorSpeedPubTopic>/motor_speed/5</motorSpeedPubTopic>
      <rotorVelocitySlowdownSim>10</rotorVelocitySlowdownSim>
    </plugin>
    <plugin filename="libgazebo_motor_model.so" name="rotor_plugin_1">
      <robotNamespace/>
      <jointName>rotor_1_joint</jointName>
      <linkName>rotor_1</linkName>
      <turningDirection>
        ccw
      </turningDirection>
      <timeConstantUp>0.0125</timeConstantUp>
      <timeConstantDown>0.025</timeConstantDown>
      <maxRotVelocity>1500</maxRotVelocity>
      <motorConstant>8.54858e-06</motorConstant>
      <momentConstant>0.06</momentConstant>
      <commandSubTopic>/gazebo/command/motor_speed</commandSubTopic>
      <motorNumber>4</motorNumber>
      <rotorDragCoefficient>0.000806428</rotorDragCoefficient>
      <rollingMomentCoefficient>1e-06</rollingMomentCoefficient>
      <motorSpeedPubTopic>/motor_speed/4</motorSpeedPubTopic>
      <rotorVelocitySlowdownSim>10</rotorVelocitySlowdownSim>
    </plugin>
    <plugin filename="libgazebo_motor_model.so" name="rotor_plugin_2">
      <robotNamespace/>
      <jointName>rotor_2_joint</jointName>
      <linkName>rotor_2</linkName>
      <turningDirection>
        ccw
      </turningDirection>
      <timeConstantUp>0.0125</timeConstantUp>
      <timeConstantDown>0.025</timeConstantDown>
      <maxRotVelocity>1500</maxRotVelocity>
      <motorConstant>8.54858e-06</motorConstant>
      <momentConstant>0.06</momentConstant>
      <commandSubTopic>/gazebo/command/motor_speed</commandSubTopic>
      <motorNumber>3</motorNumber>
      <rotorDragCoefficient>0.000806428</rotorDragCoefficient>
      <rollingMomentCoefficient>1e-06</rollingMomentCoefficient>
      <motorSpeedPubTopic>/motor_speed/3</motorSpeedPubTopic>
      <rotorVelocitySlowdownSim>10</rotorVelocitySlowdownSim>
    </plugin>
    <plugin filename="libgazebo_motor_model.so" name="rotor_plugin_3">
      <robotNamespace/>
      <jointName>rotor_3_joint</jointName>
      <linkName>rotor_3</linkName>
      <turningDirection>
        cw
      </turningDirection>
      <timeConstantUp>0.0125</timeConstantUp>
      <timeConstantDown>0.025</timeConstantDown>
      <maxRotVelocity>1500</maxRotVelocity>
      <motorConstant>8.54858e-06</motorConstant>
      <momentConstant>0.06</momentConstant>
      <commandSubTopic>/gazebo/command/motor_speed</commandSubTopic>
      <motorNumber>2</motorNumber>
      <rotorDragCoefficient>0.000806428</rotorDragCoefficient>
      <rollingMomentCoefficient>1e-06</rollingMomentCoefficient>
      <motorSpeedPubTopic>/motor_speed/2</motorSpeedPubTopic>
      <rotorVelocitySlowdownSim>10</rotorVelocitySlowdownSim>
    </plugin>
    <plugin filename="libgazebo_motor_model.so" name="rotor_plugin_4">
      <robotNamespace/>
      <jointName>rotor_4_joint</jointName>
      <linkName>rotor_4</linkName>
      <turningDirection>
        cw
      </turningDirection>
      <timeConstantUp>0.0125</timeConstantUp>
      <timeConstantDown>0.025</timeConstantDown>
      <maxRotVelocity>1500</maxRotVelocity>
      <motorConstant>8.54858e-06</motorConstant>
      <momentConstant>0.06</momentConstant>
      <commandSubTopic>/gazebo/command/motor_speed</commandSubTopic>
      <motorNumber>1</motorNumber>
      <rotorDragCoefficient>0.000806428</rotorDragCoefficient>
      <rollingMomentCoefficient>1e-06</rollingMomentCoefficient>
      <motorSpeedPubTopic>/motor_speed/1</motorSpeedPubTopic>
      <rotorVelocitySlowdownSim>10</rotorVelocitySlowdownSim>
    </plugin>
    <plugin filename="libgazebo_motor_model.so" name="rotor_plugin_5">
      <robotNamespace/>
      <jointName>rotor_5_joint</jointName>
      <linkName>rotor_5</linkName>
      <turningDirection>
        ccw
      </turningDirection>
      <timeConstantUp>0.0125</timeConstantUp>
      <timeConstantDown>0.025</timeConstantDown>
      <maxRotVelocity>1500</maxRotVelocity>
      <motorConstant>8.54858e-06</motorConstant>
      <momentConstant>0.06</momentConstant>
      <commandSubTopic>/gazebo/command/motor_speed</commandSubTopic>
      <motorNumber>0</motorNumber>
      <rotorDragCoefficient>0.000806428</rotorDragCoefficient>
      <rollingMomentCoefficient>1e-06</rollingMomentCoefficient>
      <motorSpeedPubTopic>/motor_speed/0</motorSpeedPubTopic>
      <rotorVelocitySlowdownSim>10</rotorVelocitySlowdownSim>
    </plugin>
    <plugin filename="libgazebo_groundtruth_plugin.so" name="groundtruth_plugin">
      <robotNamespace/>
    </plugin>
    <plugin filename="libgazebo_magnetometer_plugin.so" name="magnetometer_plugin">
      <robotNamespace/>
      <pubRate>100</pubRate>
      <noiseDensity>0.0004</noiseDensity>
      <randomWalk>6.4e-06</randomWalk>
      <biasCorrelationTime>600</biasCorrelationTime>
      <magTopic>/mag</magTopic>
    </plugin>
    <plugin filename="libgazebo_barometer_plugin.so" name="barometer_plugin">
      <robotNamespace/>
      <pubRate>50</pubRate>
      <baroTopic>/baro</baroTopic>
    </plugin>
    <plugin filename="libgazebo_mavlink_interface.so" name="mavlink_interface">
      <robotNamespace/>
      <imuSubTopic>/imu</imuSubTopic>
      <magSubTopic>/mag</magSubTopic>
      <baroSubTopic>/baro</baroSubTopic>
      <mavlink_addr>INADDR_ANY</mavlink_addr>
      <mavlink_tcp_port>4560</mavlink_tcp_port>
      <mavlink_udp_port>14560</mavlink_udp_port>
      <serialEnabled>0</serialEnabled>
      <serialDevice>/dev/ttyACM0</serialDevice>
      <baudRate>921600</baudRate>
      <qgc_addr>INADDR_ANY</qgc_addr>
      <qgc_udp_port>14550</qgc_udp_port>
      <sdk_addr>INADDR_ANY</sdk_addr>
      <sdk_udp_port>14540</sdk_udp_port>
      <hil_mode>0</hil_mode>
      <hil_state_level>false</hil_state_level>
      <enable_lockstep>true</enable_lockstep>
      <use_tcp>true</use_tcp>
      <motorSpeedCommandPubTopic>/gazebo/command/motor_speed</motorSpeedCommandPubTopic>
      <control_channels>
        <channel name="rotor0">
          <input_index>0</input_index>
          <input_offset>0</input_offset>
          <input_scaling>1500</input_scaling>
          <zero_position_disarmed>0</zero_position_disarmed>
          <zero_position_armed>100</zero_position_armed>
          <joint_control_type>velocity</joint_control_type>
        </channel>
        <channel name="rotor1">
          <input_index>1</input_index>
          <input_offset>0</input_offset>
          <input_scaling>1500</input_scaling>
          <zero_position_disarmed>0</zero_position_disarmed>
          <zero_position_armed>100</zero_position_armed>
          <joint_control_type>velocity</joint_control_type>
        </channel>
        <channel name="rotor2">
          <input_index>2</input_index>
          <input_offset>0</input_offset>
          <input_scaling>1500</input_scaling>
          <zero_position_disarmed>0</zero_position_disarmed>
          <zero_position_armed>100</zero_position_armed>
          <joint_control_type>velocity</joint_control_type>
        </channel>
        <channel name="rotor3">
          <input_index>3</input_index>
          <input_offset>0</input_offset>
          <input_scaling>1500</input_scaling>
          <zero_position_disarmed>0</zero_position_disarmed>
          <zero_position_armed>100</zero_position_armed>
          <joint_control_type>velocity</joint_control_type>
        </channel>
        <channel name="rotor4">
          <input_index>4</input_index>
          <input_offset>0</input_offset>
          <input_scaling>1500</input_scaling>
          <zero_position_disarmed>0</zero_position_disarmed>
          <zero_position_armed>100</zero_position_armed>
          <joint_control_type>velocity</joint_control_type>
        </channel>
        <channel name="rotor5">
          <input_index>5</input_index>
          <input_offset>0</input_offset>
          <input_scaling>1500</input_scaling>
          <zero_position_disarmed>0</zero_position_disarmed>
          <zero_position_armed>100</zero_position_armed>
          <joint_control_type>velocity</joint_control_type>
        </channel>
      </control_channels>
    </plugin>
    <plugin filename="libgazebo_imu_plugin.so" name="gazebo_imu_plugin">
      <robotNamespace/>
      <linkName>wasp/imu_link</linkName>
      <imuTopic>/imu</imuTopic>
      <gyroscopeNoiseDensity>0.0003394</gyroscopeNoiseDensity>
      <gyroscopeRandomWalk>3.8785e-05</gyroscopeRandomWalk>
      <gyroscopeBiasCorrelationTime>1000.0</gyroscopeBiasCorrelationTime>
      <gyroscopeTurnOnBiasSigma>0.0087</gyroscopeTurnOnBiasSigma>
      <accelerometerNoiseDensity>0.004</accelerometerNoiseDensity>
      <accelerometerRandomWalk>0.006</accelerometerRandomWalk>
      <accelerometerBiasCorrelationTime>300.0</accelerometerBiasCorrelationTime>
      <accelerometerTurnOnBiasSigma>0.196</accelerometerTurnOnBiasSigma>
    </plugin>
    <!--    <plugin name='camera' filename='librealsense_gazebo_plugin.so'>
      <prefix>camera</prefix>
      <depthUpdateRate>30.0</depthUpdateRate>
      <colorUpdateRate>30.0</colorUpdateRate>
      <infraredUpdateRate>30.0</infraredUpdateRate>
      <depthTopicName>depth/image_raw</depthTopicName>
      <depthCameraInfoTopicName>depth/camera_info</depthCameraInfoTopicName>
      <colorTopicName>color/image_raw</colorTopicName>
      <colorCameraInfoTopicName>color/camera_info</colorCameraInfoTopicName>
      <infrared1TopicName>infra1/image_raw</infrared1TopicName>
      <infrared1CameraInfoTopicName>infra1/camera_info</infrared1CameraInfoTopicName>
      <infrared2TopicName>infra2/image_raw</infrared2TopicName>
      <infrared2CameraInfoTopicName>infra2/camera_info</infrared2CameraInfoTopicName>
      <colorOpticalframeName>camera_color_optical_frame</colorOpticalframeName>
      <depthOpticalframeName>camera_depth_optical_frame</depthOpticalframeName>
      <infrared1OpticalframeName>camera_left_ir_optical_frame</infrared1OpticalframeName>
      <infrared2OpticalframeName>camera_right_ir_optical_frame</infrared2OpticalframeName>
      <rangeMinDepth>0.2</rangeMinDepth>
      <rangeMaxDepth>10.0</rangeMaxDepth>
      <pointCloud>1</pointCloud>
      <pointCloudTopicName>depth/color/points</pointCloudTopicName>
      <pointCloudCutoff>0.25</pointCloudCutoff>
      <pointCloudCutoffMax>9.0</pointCloudCutoffMax>
    </plugin>-->
  </gazebo>
  <!--  <xacro:include filename="$(find realsense2_description)/urdf/_d435.urdf.xacro" />
  <xacro:sensor_d435 name="camera" topics_ns="camera" parent="base_link" publish_pointcloud="false">
    <origin xyz="0 -0.070 -0.138" rpy="0 ${pi/2} ${-pi/2}" />
  </xacro:sensor_d435>-->
</robot>

